Workbook

Sheet 导入模板
A1: TK 内容中台商品档案导入模板
A2: 第 3 行为接口字段名，请不要修改；第 4 行为中文说明；从第 5 行开始填写导入数据。多值字段使用英文逗号分隔，只读字段可留空。
A3: platformCode | B3: storeName | C3: siteCode | D3: pid | E3: sku | F3: pidUsage | G3: productOperationLevelName | H3: productOperationStatusName | I3: productTags | J3: seasonTags | K3: operatorOwner | L3: businessOwner | M3: guidanceOwner | N3: editorOwner | O3: liveOwner | P3: adOwner | Q3: tagPrice | R3: dailySalePrice | S3: liveFlashPrice | T3: campaignPrice | U3: amazonPrice | V3: sitePrice | W3: publicCommissionRate | X3: targetCommissionRate | Y3: adCommissionRate | Z3: ippcRegisterStatus | AA3: ippcRemark | AB3: productSellingPoints | AC3: productAnalysis | AD3: tkProductUrl | AE3: siteProductUrl | AF3: assetFolderUrl | AG3: sourceUpdateDate | AH3: updatedTime
A4: 平台代码（必填） | B4: 所属店铺（必填） | C4: 站点代码（只读） | D4: PID / 商品 ID（必填） | E4: SKU 编码 | F4: PID 作用 | G4: 商品运营级别 | H4: 商品运营状态 | I4: 商品标签 | J4: 季节标签 | K4: 负责运营 | L4: 负责商务 | M4: 负责指导 / 编导 | N4: 负责剪辑 | O4: 直播运营 | P4: 投放负责人 | Q4: 吊牌价 | R4: 日常折线价 | S4: 直播间秒杀价 | T4: 活动报名价 | U4: 亚马逊定价 | V4: 独立站价格 | W4: 公开佣金比例 | X4: 定向佣金比例 | Y4: 广告佣金比例 | Z4: IPPC 注册情况 | AA4: IPPC 情况说明 | AB4: 产品卖点 | AC4: 商品分析说明 | AD4: TK 商品链接 | AE4: 独立站商品链接 | AF4: 素材文件夹链接 | AG4: 源数据更新日期（只读） | AH4: 档案更新时间（只读）
A5: TK | B5: 示例店铺 | C5: US | D5: PID_1729384756000000000 | E5: SKU-001-BLACK-S | F5: 主推款 | G5: A | H5: 重点运营 | I5: 新品,热卖 | J5: 春,夏 | K5: 张三 | L5: 李四 | M5: 王五 | N5: 赵六 | O5: 钱七 | P5: 孙八 | Q5: 29.99 | R5: 24.99 | S5: 19.99 | T5: 21.99 | U5: 32.99 | V5: 27.99 | W5: 10 | X5: 12 | Y5: 8 | Z5: 已注册 | AA5: 证书资料已归档 | AB5: 轻薄透气，适合夏季穿着 | AC5: 适合短视频种草和直播间转化 | AD5: https://www.tiktok.com/shop/pdp/example | AE5: https://example.com/products/demo | AF5: https://example.com/folder/demo | AG5: 2026-07-23 | AH5: 2026-07-23 10:30:00
A6: TK | B6: Faiable Fashion | C6: US | D6: 1729439482671567205 | E6: AL-W0169 | F6: 主推款 | G6: A | H6: 重点运营 | I6: 老品,热销 | J6: 秋,冬 | K6: 邹徐夏子 | L6: 张筱敏 | M6: 无 | N6: 剪辑全员 | P6: 邹徐夏子 | Q6: =VLOOKUP(E6,Sheet1!A:C,2,0) -> 99.99 | R6: =VLOOKUP(E6,Sheet1!A:C,3,0) -> AL-W0169/53.99 AL-W0150/53.99 AL-W0190B/53.99 AL-W0161/56.99 | S6: =R6 -> AL-W0169/53.99 AL-W0150/53.99 AL-W0190B/53.99 AL-W0161/56.99 | T6: =S6 -> AL-W0169/53.99 AL-W0150/53.99 AL-W0190B/53.99 AL-W0161/56.99 | U6: 53.99 | V6: 53.99 | W6: 5 | X6: 10 | Y6: 5 | Z6: 已注册 | AA6: 证书资料已归档 | AB6: 复古水洗加绒 | AD6: https://www.tiktok.com/@shop/product/1729439482671567205
A7: TK | B7: Faiable Fashion | C7: US | D7: 1729439597925077349 | E7: AL-W0169 | F7: 次推款 | G7: B | H7: 常规运营 | I7: 老品,平销 | J7: 秋,冬 | K7: 邹徐夏子 | L7: 张筱敏 | M7: 无 | N7: 暂不涉及 | P7: 邹徐夏子 | Q7: =VLOOKUP(E7,Sheet1!A:C,2,0) -> 99.99 | R7: =VLOOKUP(E7,Sheet1!A:C,3,0) -> AL-W0169/53.99 AL-W0150/53.99 AL-W0190B/53.99 AL-W0161/56.99 | S7: =R7 -> AL-W0169/53.99 AL-W0150/53.99 AL-W0190B/53.99 AL-W0161/56.99 | T7: =S7 -> AL-W0169/53.99 AL-W0150/53.99 AL-W0190B/53.99 AL-W0161/56.99 | U7: 53.99 | V7: 53.99 | W7: 5 | X7: 10 | Y7: 5 | Z7: 已注册 | AA7: 证书资料已归档 | AB7: 复古水洗加绒 | AD7: https://www.tiktok.com/@shop/product/1729439597925077349
A8: TK | B8: Faiable Fashion | C8: US | D8: 1729774299176145253 | E8: AL-W0169 | F8: 矩阵 | G8: C | H8: 基础运营 | I8: 老品,平销 | J8: 秋,冬 | K8: 邹徐夏子 | L8: 张筱敏 | M8: 无 | N8: 暂不涉及 | P8: 邹徐夏子 | Q8: =VLOOKUP(E8,Sheet1!A:C,2,0) -> 99.99 | R8: =VLOOKUP(E8,Sheet1!A:C,3,0) -> AL-W0169/53.99 AL-W0150/53.99 AL-W0190B/53.99 AL-W0161/56.99 | S8: =R8 -> AL-W0169/53.99 AL-W0150/53.99 AL-W0190B/53.99 AL-W0161/56.99 | T8: =S8 -> AL-W0169/53.99 AL-W0150/53.99 AL-W0190B/53.99 AL-W0161/56.99 | U8: 53.99 | V8: 53.99 | W8: 5 | X8: 10 | Y8: 5 | Z8: 已注册 | AA8: 证书资料已归档 | AB8: 复古水洗加绒 | AD8: https://www.tiktok.com/@shop/product/1729774299176145253
A9: TK | B9: Faiable Fashion | C9: US | D9: 1729474842401476965 | E9: AL-W0169 | F9: 矩阵 | G9: C | H9: 基础运营 | I9: 老品,平销 | J9: 秋,冬 | K9: 邹徐夏子 | L9: 张筱敏 | M9: 无 | N9: 暂不涉及 | P9: 邹徐夏子 | Q9: =VLOOKUP(E9,Sheet1!A:C,2,0) -> 99.99 | R9: =VLOOKUP(E9,Sheet1!A:C,3,0) -> AL-W0169/53.99 AL-W0150/53.99 AL-W0190B/53.99 AL-W0161/56.99 | S9: =R9 -> AL-W0169/53.99 AL-W0150/53.99 AL-W0190B/53.99 AL-W0161/56.99 | T9: =S9 -> AL-W0169/53.99 AL-W0150/53.99 AL-W0190B/53.99 AL-W0161/56.99 | U9: 53.99 | V9: 53.99 | W9: 5 | X9: 10 | Y9: 5 | Z9: 已注册 | AA9: 证书资料已归档 | AB9: 复古水洗加绒 | AD9: https://www.tiktok.com/@shop/product/1729474842401476965
A10: TK | B10: Faiable Fashion | C10: US | D10: 1731651328712937829 | E10: AL-W0169 | F10: 矩阵 | G10: C | H10: 基础运营 | I10: 老品,平销 | J10: 秋,冬 | K10: 邹徐夏子 | L10: 张筱敏 | M10: 无 | N10: 暂不涉及 | P10: 邹徐夏子 | Q10: =VLOOKUP(E10,Sheet1!A:C,2,0) -> 99.99 | R10: =VLOOKUP(E10,Sheet1!A:C,3,0) -> AL-W0169/53.99 AL-W0150/53.99 AL-W0190B/53.99 AL-W0161/56.99 | S10: =R10 -> AL-W0169/53.99 AL-W0150/53.99 AL-W0190B/53.99 AL-W0161/56.99 | T10: =S10 -> AL-W0169/53.99 AL-W0150/53.99 AL-W0190B/53.99 AL-W0161/56.99 | U10: 53.99 | V10: 53.99 | W10: 5 | X10: 10 | Y10: 5 | Z10: 已注册 | AA10: 证书资料已归档 | AB10: 复古水洗加绒 | AD10: https://www.tiktok.com/@shop/product/1731651328712937829
A11: TK | B11: Faiable Fashion | C11: US | D11: 1729876924660552037 | E11: AL-W0169 | F11: 矩阵 | G11: C | H11: 基础运营 | I11: 老品,平销 | J11: 秋,冬 | K11: 邹徐夏子 | L11: 张筱敏 | M11: 无 | N11: 暂不涉及 | P11: 邹徐夏子 | Q11: =VLOOKUP(E11,Sheet1!A:C,2,0) -> 99.99 | R11: =VLOOKUP(E11,Sheet1!A:C,3,0) -> AL-W0169/53.99 AL-W0150/53.99 AL-W0190B/53.99 AL-W0161/56.99 | S11: =R11 -> AL-W0169/53.99 AL-W0150/53.99 AL-W0190B/53.99 AL-W0161/56.99 | T11: =S11 -> AL-W0169/53.99 AL-W0150/53.99 AL-W0190B/53.99 AL-W0161/56.99 | U11: 53.99 | V11: 53.99 | W11: 5 | X11: 10 | Y11: 5 | Z11: 已注册 | AA11: 证书资料已归档 | AB11: 复古水洗加绒 | AD11: https://www.tiktok.com/@shop/product/1729876924660552037
A12: TK | B12: Faiable Fashion | C12: US | D12: 1729773126172578149 | E12: AL-W0161 | F12: 商务主推款 | G12: A | H12: 重点运营 | I12: 老品,热销 | J12: 秋,冬 | K12: 邹徐夏子 | L12: 魏芷颖 | M12: 无 | N12: 暂不涉及 | P12: 邹徐夏子 | Q12: =VLOOKUP(E12,Sheet1!A:C,2,0) -> 99.99 | R12: =VLOOKUP(E12,Sheet1!A:C,3,0) -> AL-W0169/53.99 AL-W0150/53.99 AL-W0190B/53.99 AL-W0161/56.99 | S12: =R12 -> AL-W0169/53.99 AL-W0150/53.99 AL-W0190B/53.99 AL-W0161/56.99 | T12: =S12 -> AL-W0169/53.99 AL-W0150/53.99 AL-W0190B/53.99 AL-W0161/56.99 | U12: 56.99 | V12: 56.99 | W12: 5 | X12: 10 | Y12: 5 | Z12: 已注册 | AA12: 证书资料已归档 | AB12: 复古水洗双拉连加绒 | AD12: https://www.tiktok.com/@shop/product/1729773126172578149
A13: TK | B13: Faiable Fashion | C13: US | D13: 1730674849392267621 | E13: AL-W0161 | F13: 剪辑主推款 | G13: A | H13: 重点运营 | I13: 老品,热销 | J13: 秋,冬 | K13: 邹徐夏子 | L13: 魏芷颖 | M13: 无 | N13: 剪辑全员 | P13: 邹徐夏子 | Q13: =VLOOKUP(E13,Sheet1!A:C,2,0) -> 99.99 | R13: =VLOOKUP(E13,Sheet1!A:C,3,0) -> AL-W0169/53.99 AL-W0150/53.99 AL-W0190B/53.99 AL-W0161/56.99 | S13: =R13 -> AL-W0169/53.99 AL-W0150/53.99 AL-W0190B/53.99 AL-W0161/56.99 | T13: =S13 -> AL-W0169/53.99 AL-W0150/53.99 AL-W0190B/53.99 AL-W0161/56.99 | U13: 56.99 | V13: 56.99 | W13: 5 | X13: 10 | Y13: 5 | Z13: 已注册 | AA13: 证书资料已归档 | AB13: 复古水洗双拉连加绒 | AD13: https://www.tiktok.com/@shop/product/1730674849392267621
A14: TK | B14: Faiable Fashion | C14: US | D14: 1731077240963502437 | E14: AL-W0161 | F14: 矩阵 | G14: C | H14: 基础运营 | I14: 老品,平销 | J14: 秋,冬 | K14: 邹徐夏子 | L14: 魏芷颖 | M14: 无 | N14: 暂不涉及 | P14: 邹徐夏子 | Q14: =VLOOKUP(E14,Sheet1!A:C,2,0) -> 99.99 | R14: =VLOOKUP(E14,Sheet1!A:C,3,0) -> AL-W0169/53.99 AL-W0150/53.99 AL-W0190B/53.99 AL-W0161/56.99 | S14: =R14 -> AL-W0169/53.99 AL-W0150/53.99 AL-W0190B/53.99 AL-W0161/56.99 | T14: =S14 -> AL-W0169/53.99 AL-W0150/53.99 AL-W0190B/53.99 AL-W0161/56.99 | U14: 56.99 | V14: 56.99 | W14: 5 | X14: 10 | Y14: 5 | Z14: 已注册 | AA14: 证书资料已归档 | AB14: 复古水洗双拉连加绒 | AD14: https://www.tiktok.com/@shop/product/1731077240963502437
A15: TK | B15: Faiable Fashion | C15: US | D15: 1731651043684028773 | E15: AL-W0161 | F15: 次推款 | G15: B | H15: 常规运营 | I15: 老品,平销 | J15: 秋,冬 | K15: 邹徐夏子 | L15: 魏芷颖 | M15: 无 | N15: 暂不涉及 | P15: 邹徐夏子 | Q15: =VLOOKUP(E15,Sheet1!A:C,2,0) -> 99.99 | R15: =VLOOKUP(E15,Sheet1!A:C,3,0) -> AL-W0169/53.99 AL-W0150/53.99 AL-W0190B/53.99 AL-W0161/56.99 | S15: =R15 -> AL-W0169/53.99 AL-W0150/53.99 AL-W0190B/53.99 AL-W0161/56.99 | T15: =S15 -> AL-W0169/53.99 AL-W0150/53.99 AL-W0190B/53.99 AL-W0161/56.99 | U15: 56.99 | V15: 56.99 | W15: 5 | X15: 10 | Y15: 5 | Z15: 已注册 | AA15: 证书资料已归档 | AB15: 复古水洗双拉连加绒 | AD15: https://www.tiktok.com/@shop/product/1731651043684028773
A16: TK | B16: Faiable Fashion | C16: US | D16: 1731657241623302501 | E16: AL-W0180 | F16: 商务主推款 | G16: A | H16: 重点运营 | I16: 老品,热销 | J16: 秋,冬 | K16: 邹徐夏子 | L16: 陈圻 | M16: 无 | N16: 暂不涉及 | P16: 邹徐夏子 | Q16: =VLOOKUP(E16,Sheet1!A:C,2,0) -> 99.99 | R16: =VLOOKUP(E16,Sheet1!A:C,3,0) -> 56.99 | S16: =R16 -> 56.99 | T16: =S16 -> 56.99 | U16: 56.99 | V16: =U16 -> 56.99 | W16: 5 | X16: 10 | Y16: 5 | Z16: 已注册 | AA16: 证书资料已归档 | AB16: 复古水洗半拉连加绒 | AD16: https://www.tiktok.com/@shop/product/1731657241623302501
A17: TK | B17: Faiable Fashion | C17: US | D17: 1731902422767866213 | E17: AL-W0180 | F17: 剪辑主推款 | G17: A | H17: 重点运营 | I17: 老品,热销 | J17: 秋,冬 | K17: 邹徐夏子 | L17: 陈圻 | M17: 无 | N17: 剪辑全员 | P17: 邹徐夏子 | Q17: =VLOOKUP(E17,Sheet1!A:C,2,0) -> 99.99 | R17: =VLOOKUP(E17,Sheet1!A:C,3,0) -> 56.99 | S17: =R17 -> 56.99 | T17: =S17 -> 56.99 | U17: 56.99 | V17: =U17 -> 56.99 | W17: 5 | X17: 10 | Y17: 5 | Z17: 已注册 | AA17: 证书资料已归档 | AB17: 复古水洗半拉连加绒 | AD17: https://www.tiktok.com/@shop/product/1731902422767866213
A18: TK | B18: Faiable Fashion | C18: US | D18: 1729474118118249829 | E18: AL-W0180 | F18: 矩阵 | G18: C | H18: 基础运营 | I18: 老品,平销 | J18: 秋,冬 | K18: 邹徐夏子 | L18: 陈圻 | M18: 无 | N18: 暂不涉及 | P18: 邹徐夏子 | Q18: =VLOOKUP(E18,Sheet1!A:C,2,0) -> 99.99 | R18: =VLOOKUP(E18,Sheet1!A:C,3,0) -> 56.99 | S18: =R18 -> 56.99 | T18: =S18 -> 56.99 | U18: 56.99 | V18: =U18 -> 56.99 | W18: 5 | X18: 10 | Y18: 5 | Z18: 已注册 | AA18: 证书资料已归档 | AB18: 复古水洗半拉连加绒 | AD18: https://www.tiktok.com/@shop/product/1729474118118249829
A19: TK | B19: Faiable Fashion | C19: US | D19: 1731186747983171941 | E19: AL-W0518 | F19: 主推款 | G19: A | H19: 重点运营 | I19: 老品,热销 | J19: 春,夏 | K19: 邹徐夏子 | L19: 暂不涉及 | M19: 无 | N19: 剪辑全员 | P19: 邹徐夏子 | Q19: =VLOOKUP(E19,Sheet1!A:C,2,0) -> 36.99 | R19: =VLOOKUP(E19,Sheet1!A:C,3,0) -> 19.99 | S19: =R19 -> 19.99 | T19: =S19 -> 19.99 | U19: =T19 -> 19.99 | V19: =U19 -> 19.99 | W19: 5 | X19: 10 | Y19: 5 | Z19: 已注册 | AA19: 证书资料已归档 | AB19: 轻便卷边半透明 | AD19: https://www.tiktok.com/@shop/product/1731186747983171941
A20: TK | B20: Faiable Fashion | C20: US | D20: 1731777596597178725 | E20: AL-W0518 | F20: 矩阵 | G20: C | H20: 基础运营 | I20: 老品,平销 | J20: 春,夏 | K20: 邹徐夏子 | L20: 暂不涉及 | M20: 无 | N20: 暂不涉及 | P20: 邹徐夏子 | Q20: =VLOOKUP(E20,Sheet1!A:C,2,0) -> 36.99 | R20: =VLOOKUP(E20,Sheet1!A:C,3,0) -> 19.99 | S20: =R20 -> 19.99 | T20: =S20 -> 19.99 | U20: =T20 -> 19.99 | V20: =U20 -> 19.99 | W20: 5 | X20: 10 | Y20: 5 | Z20: 已注册 | AA20: 证书资料已归档 | AB20: 轻便卷边半透明 | AD20: https://www.tiktok.com/@shop/product/1731777596597178725
A21: TK | B21: Faiable Fashion | C21: US | D21: 1729439778991083877 | E21: AL-W0190B | F21: 清仓款 | G21: D | H21: 基础运营 | I21: 老品,滞销 | J21: 秋,冬 | K21: 邹徐夏子 | L21: 暂不涉及 | M21: 无 | N21: 暂不涉及 | P21: 邹徐夏子 | Q21: =VLOOKUP(E21,Sheet1!A:C,2,0) -> 99.99 | R21: =VLOOKUP(E21,Sheet1!A:C,3,0) -> 53.99 | S21: =R21 -> 53.99 | T21: =S21 -> 53.99 | U21: =T21 -> 53.99 | V21: =U21 -> 53.99 | W21: 5 | X21: 10 | Y21: 5 | Z21: 已注册 | AA21: 证书资料已归档 | AB21: 复古水洗加绒 | AD21: https://www.tiktok.com/@shop/product/1729439778991083877
A22: TK | B22: Faiable Fashion | C22: US | D22: 1729445816792093029 | E22: AL-W0190B | F22: 矩阵 | G22: C | H22: 基础运营 | I22: 老品,滞销 | J22: 秋,冬 | K22: 邹徐夏子 | L22: 暂不涉及 | M22: 无 | N22: 暂不涉及 | P22: 邹徐夏子 | Q22: =VLOOKUP(E22,Sheet1!A:C,2,0) -> 99.99 | R22: =VLOOKUP(E22,Sheet1!A:C,3,0) -> 53.99 | S22: =R22 -> 53.99 | T22: =S22 -> 53.99 | U22: =T22 -> 53.99 | V22: =U22 -> 53.99 | W22: 5 | X22: 10 | Y22: 5 | Z22: 已注册 | AA22: 证书资料已归档 | AB22: 复古水洗加绒 | AD22: https://www.tiktok.com/@shop/product/1729445816792093029
A23: TK | B23: Faiable Fashion | C23: US | D23: 1731652088708829541 | E23: AL-W0190B | F23: 矩阵 | G23: C | H23: 基础运营 | I23: 老品,滞销 | J23: 秋,冬 | K23: 邹徐夏子 | L23: 暂不涉及 | M23: 无 | N23: 暂不涉及 | P23: 邹徐夏子 | Q23: =VLOOKUP(E23,Sheet1!A:C,2,0) -> 99.99 | R23: =VLOOKUP(E23,Sheet1!A:C,3,0) -> 53.99 | S23: =R23 -> 53.99 | T23: =S23 -> 53.99 | U23: =T23 -> 53.99 | V23: =U23 -> 53.99 | W23: 5 | X23: 10 | Y23: 5 | Z23: 已注册 | AA23: 证书资料已归档 | AB23: 复古水洗加绒 | AD23: https://www.tiktok.com/@shop/product/1731652088708829541
A24: TK | B24: Faiable Fashion | C24: US | D24: 1729446258071540069 | E24: AL-W0190B | F24: 矩阵 | G24: C | H24: 基础运营 | I24: 老品,滞销 | J24: 秋,冬 | K24: 邹徐夏子 | L24: 暂不涉及 | M24: 无 | N24: 暂不涉及 | P24: 邹徐夏子 | Q24: =VLOOKUP(E24,Sheet1!A:C,2,0) -> 99.99 | R24: =VLOOKUP(E24,Sheet1!A:C,3,0) -> 53.99 | S24: =R24 -> 53.99 | T24: =S24 -> 53.99 | U24: =T24 -> 53.99 | V24: =U24 -> 53.99 | W24: 5 | X24: 10 | Y24: 5 | Z24: 已注册 | AA24: 证书资料已归档 | AB24: 复古水洗加绒 | AD24: https://www.tiktok.com/@shop/product/1729446258071540069
A25: TK | B25: Faiable Fashion | C25: US | D25: 1729442841715118437 | E25: AL-W0150 | F25: 清仓款 | G25: D | H25: 基础运营 | I25: 老品,滞销 | J25: 秋,冬 | K25: 邹徐夏子 | L25: 暂不涉及 | M25: 无 | N25: 暂不涉及 | P25: 邹徐夏子 | Q25: =VLOOKUP(E25,Sheet1!A:C,2,0) -> 69.99 | R25: =VLOOKUP(E25,Sheet1!A:C,3,0) -> 53.99 | S25: =R25 -> 53.99 | T25: =S25 -> 53.99 | U25: =T25 -> 53.99 | V25: =U25 -> 53.99 | W25: 5 | X25: 10 | Y25: 5 | Z25: 已注册 | AA25: 证书资料已归档 | AB25: 复古水洗加绒 | AD25: https://www.tiktok.com/@shop/product/1729442841715118437
A26: TK | B26: Faiable Fashion | C26: US | D26: 1729441624458432869 | E26: AL-W0150 | F26: 矩阵 | G26: C | H26: 基础运营 | I26: 老品,滞销 | J26: 秋,冬 | K26: 邹徐夏子 | L26: 暂不涉及 | M26: 无 | N26: 暂不涉及 | P26: 邹徐夏子 | Q26: =VLOOKUP(E26,Sheet1!A:C,2,0) -> 69.99 | R26: =VLOOKUP(E26,Sheet1!A:C,3,0) -> 53.99 | S26: =R26 -> 53.99 | T26: =S26 -> 53.99 | U26: =T26 -> 53.99 | V26: =U26 -> 53.99 | W26: 5 | X26: 10 | Y26: 5 | Z26: 已注册 | AA26: 证书资料已归档 | AB26: 复古水洗加绒 | AD26: https://www.tiktok.com/@shop/product/1729441624458432869
A27: TK | B27: Faiable Fashion | C27: US | D27: 1731653782107951461 | E27: AL-W0150 | F27: 矩阵 | G27: C | H27: 基础运营 | I27: 老品,滞销 | J27: 秋,冬 | K27: 邹徐夏子 | L27: 暂不涉及 | M27: 无 | N27: 暂不涉及 | P27: 邹徐夏子 | Q27: =VLOOKUP(E27,Sheet1!A:C,2,0) -> 69.99 | R27: =VLOOKUP(E27,Sheet1!A:C,3,0) -> 53.99 | S27: =R27 -> 53.99 | T27: =S27 -> 53.99 | U27: =T27 -> 53.99 | V27: =U27 -> 53.99 | W27: 5 | X27: 10 | Y27: 5 | Z27: 已注册 | AA27: 证书资料已归档 | AB27: 复古水洗加绒 | AD27: https://www.tiktok.com/@shop/product/1731653782107951461
A28: TK | B28: Faiable Fashion | C28: US | D28: 1729439383361524069 | E28: AL-W0150 | F28: 矩阵 | G28: C | H28: 基础运营 | I28: 老品,滞销 | J28: 秋,冬 | K28: 邹徐夏子 | L28: 暂不涉及 | M28: 无 | N28: 暂不涉及 | P28: 邹徐夏子 | Q28: =VLOOKUP(E28,Sheet1!A:C,2,0) -> 69.99 | R28: =VLOOKUP(E28,Sheet1!A:C,3,0) -> 53.99 | S28: =R28 -> 53.99 | T28: =S28 -> 53.99 | U28: =T28 -> 53.99 | V28: =U28 -> 53.99 | W28: 5 | X28: 10 | Y28: 5 | Z28: 已注册 | AA28: 证书资料已归档 | AB28: 复古水洗加绒 | AD28: https://www.tiktok.com/@shop/product/1729439383361524069
A29: TK | B29: Faiable Fashion | C29: US | D29: 1732152447352541541 | E29: ALYMX-DROPSW | F29: 滞销款 | G29: D | H29: 基础运营 | I29: 老品,滞销 | J29: 秋,冬 | K29: 邹徐夏子 | L29: 暂不涉及 | M29: 无 | N29: 暂不涉及 | P29: 邹徐夏子 | Q29: =VLOOKUP(E29,Sheet1!A:C,2,0) -> 49.99 | R29: =VLOOKUP(E29,Sheet1!A:C,3,0) -> 39.99 | S29: =R29 -> 39.99 | T29: =S29 -> 39.99 | U29: =T29 -> 39.99 | V29: =U29 -> 39.99 | W29: 5 | X29: 10 | Y29: 5 | Z29: 已注册 | AA29: 证书资料已归档 | AB29: 短款v领复古水洗 | AD29: https://www.tiktok.com/@shop/product/1732152447352541541
A30: TK | B30: Faiable Fashion | C30: US | D30: 1729439569128755557 | E30: ALYMX-DROPSW | F30: 矩阵 | G30: C | H30: 基础运营 | I30: 老品,滞销 | J30: 秋,冬 | K30: 邹徐夏子 | L30: 暂不涉及 | M30: 无 | N30: 暂不涉及 | P30: 邹徐夏子 | Q30: =VLOOKUP(E30,Sheet1!A:C,2,0) -> 49.99 | R30: =VLOOKUP(E30,Sheet1!A:C,3,0) -> 39.99 | S30: =R30 -> 39.99 | T30: =S30 -> 39.99 | U30: =T30 -> 39.99 | V30: =U30 -> 39.99 | W30: 5 | X30: 10 | Y30: 5 | Z30: 已注册 | AA30: 证书资料已归档 | AB30: 短款v领复古水洗 | AD30: https://www.tiktok.com/@shop/product/1729439569128755557
... A36: TK | B36: Faiable Fashion | C36: US | D36: 1730664352968905061 | E36: AL-W0199 | F36: 矩阵 | G36: C | H36: 基础运营 | I36: 老品,平销 | J36: 秋,冬 | K36: 邹徐夏子 | L36: 暂不涉及 | M36: 无 | N36: 暂不涉及 | P36: 邹徐夏子 | Q36: =VLOOKUP(E36,Sheet1!A:C,2,0) -> 69.99 | R36: =VLOOKUP(E36,Sheet1!A:C,3,0) -> 53.99 | S36: =R36 -> 53.99 | T36: =S36 -> 53.99 | U36: =T36 -> 53.99 | V36: =U36 -> 53.99 | W36: 5 | X36: 10 | Y36: 5 | Z36: 已注册 | AA36: 证书资料已归档 | AB36: 情人节 | AD36: https://www.tiktok.com/@shop/product/1730664352968905061
A37: TK | B37: Faiable Fashion | C37: US | D37: 1730614794040807781 | E37: AL-W2467 | F37: 清仓款 | G37: D | H37: 基础运营 | I37: 老品,滞销 | J37: 秋,冬 | K37: 邹徐夏子 | L37: 暂不涉及 | M37: 无 | N37: 暂不涉及 | P37: 邹徐夏子 | Q37: =VLOOKUP(E37,Sheet1!A:C,2,0) -> 69.99 | R37: =VLOOKUP(E37,Sheet1!A:C,3,0) -> 53.99 | S37: =R37 -> 53.99 | T37: =S37 -> 53.99 | U37: =T37 -> 53.99 | V37: =U37 -> 53.99 | W37: 5 | X37: 10 | Y37: 5 | Z37: 已注册 | AA37: 证书资料已归档 | AD37: https://www.tiktok.com/@shop/product/1730614794040807781
A38: TK | B38: Faiable Fashion | C38: US | D38: 1730673744405238117 | E38: AL-W2467 | F38: 矩阵 | G38: C | H38: 基础运营 | I38: 老品,滞销 | J38: 秋,冬 | K38: 邹徐夏子 | L38: 暂不涉及 | M38: 无 | N38: 暂不涉及 | P38: 邹徐夏子 | Q38: =VLOOKUP(E38,Sheet1!A:C,2,0) -> 69.99 | R38: =VLOOKUP(E38,Sheet1!A:C,3,0) -> 53.99 | S38: =R38 -> 53.99 | T38: =S38 -> 53.99 | U38: =T38 -> 53.99 | V38: =U38 -> 53.99 | W38: 5 | X38: 10 | Y38: 5 | Z38: 已注册 | AA38: 证书资料已归档 | AD38: https://www.tiktok.com/@shop/product/1730673744405238117
A39: TK | B39: Faiable Fashion | C39: US | D39: 1729799431028707685 | E39: AL-1138 | F39: 清仓款 | G39: D | H39: 基础运营 | I39: 老品,滞销 | J39: 秋,冬 | K39: 邹徐夏子 | L39: 暂不涉及 | M39: 无 | N39: 暂不涉及 | P39: 邹徐夏子 | Q39: =VLOOKUP(E39,Sheet1!A:C,2,0) -> 59.99 | R39: =VLOOKUP(E39,Sheet1!A:C,3,0) -> 49.99 | S39: =R39 -> 49.99 | T39: =S39 -> 49.99 | U39: =T39 -> 49.99 | V39: =U39 -> 49.99 | W39: 5 | X39: 10 | Y39: 5 | Z39: 已注册 | AA39: 证书资料已归档 | AB39: 复古水洗加绒 | AD39: https://www.tiktok.com/@shop/product/1729799431028707685
A40: TK | B40: Faiable Fashion | C40: US | D40: 1729941138102063461 | E40: AL-1138 | F40: 矩阵 | G40: C | H40: 基础运营 | I40: 老品,滞销 | J40: 秋,冬 | K40: 邹徐夏子 | L40: 暂不涉及 | M40: 无 | N40: 暂不涉及 | P40: 邹徐夏子 | Q40: =VLOOKUP(E40,Sheet1!A:C,2,0) -> 59.99 | R40: =VLOOKUP(E40,Sheet1!A:C,3,0) -> 49.99 | S40: =R40 -> 49.99 | T40: =S40 -> 49.99 | U40: =T40 -> 49.99 | V40: =U40 -> 49.99 | W40: 5 | X40: 10 | Y40: 5 | Z40: 已注册 | AA40: 证书资料已归档 | AB40: 复古水洗加绒 | AD40: https://www.tiktok.com/@shop/product/1729941138102063461
A41: TK | B41: Faiable Fashion | C41: US | D41: 1730569205741031781 | E41: AL-W1189 | F41: 清仓款 | G41: D | H41: 基础运营 | I41: 老品,滞销 | J41: 秋,冬 | K41: 邹徐夏子 | L41: 暂不涉及 | M41: 无 | N41: 暂不涉及 | P41: 邹徐夏子 | Q41: =VLOOKUP(E41,Sheet1!A:C,2,0) -> 69.99 | R41: =VLOOKUP(E41,Sheet1!A:C,3,0) -> 53.99 | S41: =R41 -> 53.99 | T41: =S41 -> 53.99 | U41: =T41 -> 53.99 | V41: =U41 -> 53.99 | W41: 5 | X41: 10 | Y41: 5 | Z41: 已注册 | AA41: 证书资料已归档 | AB41: 复古水洗加绒 | AD41: https://www.tiktok.com/@shop/product/1730569205741031781
A42: TK | B42: Faiable Fashion | C42: US | D42: 1730664447555899749 | E42: AL-W1189 | F42: 矩阵 | G42: C | H42: 基础运营 | I42: 老品,滞销 | J42: 秋,冬 | K42: 邹徐夏子 | L42: 暂不涉及 | M42: 无 | N42: 暂不涉及 | P42: 邹徐夏子 | Q42: =VLOOKUP(E42,Sheet1!A:C,2,0) -> 69.99 | R42: =VLOOKUP(E42,Sheet1!A:C,3,0) -> 53.99 | S42: =R42 -> 53.99 | T42: =S42 -> 53.99 | U42: =T42 -> 53.99 | V42: =U42 -> 53.99 | W42: 5 | X42: 10 | Y42: 5 | Z42: 已注册 | AA42: 证书资料已归档 | AB42: 复古水洗加绒 | AD42: https://www.tiktok.com/@shop/product/1730664447555899749
A43: TK | B43: Faiable Fashion | C43: US | D43: 1730075990024360293 | E43: AL-WT2404 | F43: 次推款 | G43: B | H43: 常规运营 | I43: 老品,滞销 | J43: 秋,冬 | K43: 邹徐夏子 | L43: 暂不涉及 | M43: 无 | N43: 暂不涉及 | P43: 邹徐夏子 | Q43: =VLOOKUP(E43,Sheet1!A:C,2,0) -> 65.99 | R43: 45.99 | S43: 45.99 | T43: 45.99 | U43: 45.99 | V43: =U43 -> 45.99 | W43: 5 | X43: 10 | Y43: 5 | Z43: 已注册 | AA43: 证书资料已归档 | AB43: 复古水洗加绒斜肩 | AD43: https://www.tiktok.com/@shop/product/1730075990024360293
A44: TK | B44: Faiable Fashion | C44: US | D44: 1730216955590185317 | E44: AL-SZ2405 | F44: 次推款 | G44: B | H44: 常规运营 | I44: 老品,滞销 | J44: 秋,冬 | K44: 邹徐夏子 | L44: 暂不涉及 | M44: 无 | N44: 暂不涉及 | P44: 邹徐夏子 | Q44: =VLOOKUP(E44,Sheet1!A:C,2,0) -> 65.99 | R44: 45.99 | S44: 45.99 | T44: 45.99 | U44: 45.99 | V44: =U44 -> 45.99 | W44: 5 | X44: 10 | Y44: 5 | Z44: 已注册 | AA44: 证书资料已归档 | AB44: 复古水洗加绒斜肩 | AD44: https://www.tiktok.com/@shop/product/1730216955590185317
A45: TK | B45: Faiable Fashion | C45: US | D45: 1730064296603062629 | E45: AL-WY2410 | F45: 清仓款 | G45: D | H45: 基础运营 | I45: 老品,滞销 | J45: 秋,冬 | K45: 邹徐夏子 | L45: 暂不涉及 | M45: 无 | N45: 暂不涉及 | P45: 邹徐夏子 | Q45: =VLOOKUP(E45,Sheet1!A:C,2,0) -> 69.99 | R45: =VLOOKUP(E45,Sheet1!A:C,3,0) -> 45.99 | S45: =R45 -> 45.99 | T45: =S45 -> 45.99 | U45: 53.99 | V45: =U45 -> 53.99 | W45: 5 | X45: 10 | Y45: 5 | Z45: 已注册 | AA45: 证书资料已归档 | AD45: https://www.tiktok.com/@shop/product/1730064296603062629
...

Sheet 字段说明
A1: 接口字段名 | B1: 中文名 | C1: 类型 | D1: 是否导入保存 | E1: 是否必填 | F1: 字段说明 | G1: 示例
A2: platformCode | B2: 平台代码 | C2: 文本 | D2: 是 | E2: 是 | F2: 平台代码 | G2: TK
A3: storeName | B3: 所属店铺 | C3: 文本 | D3: 是 | E3: 是 | F3: 所属店铺 | G3: 示例店铺
A4: siteCode | B4: 站点代码 | C4: 文本 | D4: 否，只读返回字段 | E4: 否 | F4: 站点代码，详情返回字段 | G4: US
A5: pid | B5: PID / 商品 ID | C5: 文本 | D5: 是 | E5: 是 | F5: TikTok 商品 ID / 平台商品 ID | G5: PID_1729384756000000000
A6: sku | B6: SKU 编码 | C6: 文本 | D6: 是 | E6: 否 | F6: SKU 编码 | G6: SKU-001-BLACK-S
A7: spu | B7: 产品主 SPU | C7: 文本 | D7: 是 | E7: 否 | F7: 产品主 SPU | G7: SPU-001
A8: mainSku | B8: 产品主 SKU | C8: 文本 | D8: 是 | E8: 否 | F8: 产品主 SKU，价格归属该 SKU | G8: SKU-001-BLACK-S
A9: colorName | B9: 颜色 | C9: 文本 | D9: 是 | E9: 否 | F9: 颜色 | G9: 黑色
A10: sizeName | B10: 尺码 | C10: 文本 | D10: 是 | E10: 否 | F10: 尺码 | G10: S
A11: skuNameCn | B11: SKU 中文名 | C11: 文本 | D11: 是 | E11: 否 | F11: SKU 中文名 | G11: 示例商品 黑色 S
A12: sellableStockQty | B12: 可售库存 | C12: 整数 | D12: 否，只读返回字段 | E12: 否 | F12: 可售库存，详情返回字段，不参与保存 | G12: 128
A13: productNameCn | B13: 产品中文名 | C13: 文本 | D13: 是 | E13: 否 | F13: 产品中文名 | G13: 示例商品
A14: productStatus | B14: 商品状态 | C14: 文本 | D14: 是 | E14: 否 | F14: 商品状态 / 销售状态 | G14: 在售
A15: tkAuditStatus | B15: TK 审核状态 | C15: 文本 | D15: 否，只读返回字段 | E15: 否 | F15: TK 审核状态，只读，不参与保存 | G15: 审核通过
A16: pidUsage | B16: PID 作用 | C16: 文本 | D16: 是 | E16: 否 | F16: PID 作用 | G16: 主推款
A17: productBrand | B17: 产品品牌 | C17: 文本 | D17: 是 | E17: 否 | F17: 产品品牌 | G17: 示例品牌
A18: productCategory | B18: 产品品类 | C18: 文本 | D18: 是 | E18: 否 | F18: 产品品类 | G18: 服饰
A19: productOperationLevelName | B19: 商品运营级别 | C19: 文本 | D19: 是 | E19: 否 | F19: 商品运营级别 | G19: A
A20: productOperationStatusName | B20: 商品运营状态 | C20: 文本 | D20: 是 | E20: 否 | F20: 商品运营状态 | G20: 重点运营
A21: productTags | B21: 商品标签 | C21: 多值文本 | D21: 是 | E21: 否 | F21: 商品标签，多值用英文逗号分隔 | G21: 新品,热卖
A22: seasonTags | B22: 季节标签 | C22: 多值文本 | D22: 是 | E22: 否 | F22: 季节标签，多值用英文逗号分隔，可填：春,夏,秋,冬 | G22: 春,夏
A23: operatorOwner | B23: 负责运营 | C23: 文本 | D23: 是 | E23: 否 | F23: 负责运营 | G23: 张三
A24: businessOwner | B24: 负责商务 | C24: 文本 | D24: 是 | E24: 否 | F24: 负责商务 | G24: 李四
... A28: adOwner | B28: 投放负责人 | C28: 文本 | D28: 是 | E28: 否 | F28: 投放负责人 | G28: 孙八
A29: tagPrice | B29: 吊牌价 | C29: 小数 | D29: 是 | E29: 否 | F29: 吊牌价，保留 2 位小数 | G29: 29.99
A30: dailySalePrice | B30: 日常折线价 | C30: 小数 | D30: 是 | E30: 否 | F30: 日常折线价，保留 2 位小数 | G30: 24.99
A31: liveFlashPrice | B31: 直播间秒杀价 | C31: 小数 | D31: 是 | E31: 否 | F31: 直播间秒杀价，保留 2 位小数 | G31: 19.99
A32: campaignPrice | B32: 活动报名价 | C32: 小数 | D32: 是 | E32: 否 | F32: 活动报名价，保留 2 位小数 | G32: 21.99
A33: amazonPrice | B33: 亚马逊定价 | C33: 小数 | D33: 是 | E33: 否 | F33: 亚马逊定价，保留 2 位小数 | G33: 32.99
A34: sitePrice | B34: 独立站价格 | C34: 小数 | D34: 是 | E34: 否 | F34: 独立站价格，保留 2 位小数 | G34: 27.99
A35: publicCommissionRate | B35: 公开佣金比例 | C35: 小数 | D35: 是 | E35: 否 | F35: 公开佣金比例，按接口返回格式填写，如 10.00 | G35: 10
A36: targetCommissionRate | B36: 定向佣金比例 | C36: 小数 | D36: 是 | E36: 否 | F36: 定向佣金比例，按接口返回格式填写，如 12.00 | G36: 12
A37: adCommissionRate | B37: 广告佣金比例 | C37: 小数 | D37: 是 | E37: 否 | F37: 广告佣金比例，按接口返回格式填写，如 8.00 | G37: 8
A38: ippcRegisterStatus | B38: IPPC 注册情况 | C38: 文本 | D38: 是 | E38: 否 | F38: IPPC 注册情况 | G38: 已注册
A39: ippcRemark | B39: IPPC 情况说明 | C39: 长文本 | D39: 是 | E39: 否 | F39: IPPC 情况说明 | G39: 证书资料已归档
A40: productSellingPoints | B40: 产品卖点 | C40: 长文本 | D40: 是 | E40: 否 | F40: 产品卖点 | G40: 轻薄透气，适合夏季穿着
A41: productAnalysis | B41: 商品分析说明 | C41: 长文本 | D41: 是 | E41: 否 | F41: 商品分析说明 | G41: 适合短视频种草和直播间转化
A42: tkProductUrl | B42: TK 商品链接 | C42: URL | D42: 是 | E42: 否 | F42: TK 商品链接 | G42: https://www.tiktok.com/shop/pdp/example
A43: siteProductUrl | B43: 独立站商品链接 | C43: URL | D43: 是 | E43: 否 | F43: 独立站商品链接 | G43: https://example.com/products/demo
...

Sheet 填写选项
A1: seasonTags 可选值
A2: 春
A3: 夏
A4: 秋
A5: 冬
A7: 填写说明
A8: 多选时在同一个单元格内用英文逗号分隔，例如：春,夏
A9: 只读字段来自详情返回，不参与保存导入，可留空

Sheet Sheet1
A1: AL-W0169 | B1: 99.99 | C1: AL-W0169/53.99 AL-W0150/53.99 AL-W0190B/53.99 AL-W0161/56.99
A2: AL-W0169 | B2: 69.99 | C2: 53.99
A3: AL-W0169 | B3: 99.99 | C3: AL-W0169/53.99 AL-W0150/53.99 AL-W0190B/53.99
A4: AL-W0169 | B4: 99.99 | C4: AL-W0169/53.99 AL-W0150/53.99 AL-W0190B/53.99 AL-W0161/56.99
A5: AL-W0169 | B5: 99.99 | C5: 53.99
A6: AL-W0169 | B6: 69.99 | C6: 53.99
A7: AL-W0161 | B7: 99.99 | C7: AL-W0169/53.99 AL-W0150/53.99 AL-W0190B/53.99 AL-W0161/56.99
A8: AL-W0161 | B8: 99.99 | C8: 56.99
A9: AL-W0161 | B9: 69.99 | C9: 56.99
A10: AL-W0161 | B10: 99.99 | C10: 56.99
A11: AL-W0180 | B11: 99.99 | C11: 56.99
A12: AL-W0180 | B12: 99.99 | C12: 56.99
A13: AL-W0180 | B13: 99.99 | C13: 56.99
A14: AL-W0518 | B14: 36.99 | C14: 19.99
A15: AL-W0518 | B15: 36.99 | C15: 19.99
A16: AL-W0190B | B16: 99.99 | C16: 53.99
A17: AL-W0190B | B17: 69.99 | C17: 53.99
A18: AL-W0190B | B18: 99.99 | C18: 53.99
A19: AL-W0190B | B19: 69.99 | C19: 53.99
... A22: AL-W0150 | B22: 99.99 | C22: 53.99
A23: AL-W0150 | B23: 69.99 | C23: AL-W0169/53.99 AL-W0150/53.99 AL-W0190B/53.99
A24: ALYMX-DROPSW | B24: 49.99 | C24: 39.99
A25: ALYMX-DROPSW | B25: 49.99 | C25: 39.99
A26: ALYMX-DROPSW | B26: 49.99 | C26: 39.99
A27: ALYMX-DROPSW | B27: 49.99 | C27: 39.99
A28: ALYMX-DROPSW | B28: 49.99 | C28: 39.99
A29: ALYMX-DROPSW | B29: 49.99 | C29: 39.99
A30: AL-W0199 | B30: 69.99 | C30: 53.99
A31: AL-W0199 | B31: 69.99 | C31: 53.99
A32: AL-W2467 | B32: 69.99 | C32: 53.99
A33: AL-W2467 | B33: 69.99 | C33: 53.99
A34: AL-1138 | B34: 59.99 | C34: 49.99
A35: AL-1138 | B35: 59.99 | C35: 49.99
... A37: AL-W1189 | B37: 69.99 | C37: 53.99
A38: AL-WT2404 | B38: 65.99 | C38: AL-SZ2405/45.99 AL-WT2404/45.99
A39: AL-SZ2405 | B39: 65.99 | C39: AL-SZ2405/45.99 AL-WT2404/45.99
A40: AL-WY2410 | B40: 69.99 | C40: 45.99
A41: N26 | B41: 66.65 | C41: 39.99
A42: AL-W0166 | B42: 69.99 | C42: 39.99
A43: AL-W0166 | B43: 69.99 | C43: 39.99
...

Sheet Sheet2
A1: AL-W5558 | B1: 36.99
A2: AL-W0166 | B2: 39.99
A3: AL-BX04 | B3: 32.99
A4: AL-Z01 | B4: 39.99
A5: E24B03863PC | B5: 29.99
A6: AL-W0660 | B6: 14.99
A7: AL-W0661 | B7: 19.99
A8: AL-W0667 | B8: 14.99
A9: AL-W0668 | B9: 14.99
A10: AL-W8517 | B10: 29.99
A11: AL-JH011 | B11: 29.99
A12: AL-W7512 | B12: 32.99
... A14: AL-DG6491 | B14: 53.99
A15: E25T2012
A16: AL-EKWC
A17: AL-MMTZ02 | B17: 37.99
A18: AL-W1912 | B18: 27.99
A19: AL-HANZ06 | B19: 35.99
A20: AL-HANZ01 | B20: 39.99
A21: AL-HANZ03 | B21: 39.99
A22: AL-W0122 | B22: 35.99
A23: AL-W0126 | B23: 43.99
A24: AL-W0181 | B24: 53.99
A25: AL-W0575 | B25: 49.99
A26: AL-W6666 | B26: 49.99
A27: AL-W0165 | B27: 29.99
A28: AL-W6679 | B28: 32.99
... A75: C-6251H | B75: 56.99
A76: AL-W0780 | B76: /
A77: AL-W0781 | B77: /
A78: AL-W0782 | B78: /
A79: AL-W0588 | B79: 19.99
A80: AL-W6605 | B80: 19.99
A81: AL-W6612 | B81: 19.99
A82: AL-W6671 | B82: 19.99
A83: AL-W6872 | B83: 19.99
A84: AL-W6875 | B84: 19.99
A85: AL-W8102 | B85: 29.99
A86: AL-W8106 | B86: 23.99
A87: AL-W6613 | B87: 29.99
...

Sheet Sheet3
A1: 1729552862134243370 | B1: 65.99 | C1: 45.99
A2: 1730406615022669866 | B2: 65.99 | C2: 45.99
A3: 1730731625513717802 | B3: 65.99 | C3: 45.99
A4: 1730073982466953258 | B4: 69.99 | C4: 56.99
A5: 1731941270275264554 | B5: 99.99 | C5: 56.99
A6: 1731942257152921642 | B6: 99.99 | C6: 56.99
A7: 1731952250585255978 | B7: 99.99 | C7: 53.99
A8: 1730210822250598442 | B8: 65.99 | C8: 45.99
A9: 1729608494787760170 | B9: 69.99 | C9: 53.99
A10: 1729553028425158698 | B10: 69.99 | C10: 53.99
A11: 1729548635084197930 | B11: 49.99 | C11: 39.99
A12: 1731934152814399530 | B12: 49.99 | C12: 39.99
A13: 1730068115010719786 | B13: 59.99 | C13: 49.99
A14: 1730076674489290794 | B14: 59.99 | C14: 45.99
A15: 1730575956299124778 | B15: 69.99 | C15: 45.99
A16: 1730576639159603242 | B16: 69.99 | C16: 53.99
A17: 1730627578650595370 | B17: 69.99 | C17: 53.99
A18: 1730631160004775978 | B18: 65.99 | C18: 49.99
A19: 1731634535437733930 | B19: 66.99 | C19: 42.99
A20: 1731676926776610858 | B20: 99.99 | C20: 59.99
A21: 1731993037739167786 | B21: 99.99 | C21: 59.99
A22: 1731993745678438442 | B22: 99.99 | C22: 59.99
... A39: 1729557973439255361 | B39: 69.99 | C39: 45.99
A40: 1730074813002519361 | B40: 65..99 | C40: AL-WT2404/37.99 AL-SZ2405/37.99
A41: 1730215849898644289 | B41: 65..99 | C41: 45.99
A42: 1731708662655652673 | B42: 99.99 | C42: 39.99
A43: 1729477305515610945 | B43: 69.99 | C43: 45.99
A44: 1729551730326016833 | B44: 69.99 | C44: 48.99
A45: 1730067579663455041 | B45: 59.99 | C45: 41.99
A46: 1730073695612736321 | B46: 49.99 | C46: 31.99
A47: 1730064798499050305 | B47: 59.99 | C47: 45.99
A48: 1730576065799230273 | B48: 69.99 | C48: 45.99
A49: 1730576464737112897 | B49: 69.99 | C49: 45.99
A50: 1730614856728089409 | B50: 69.99 | C50: 45.99
A51: 1730631155438097217 | B51: 65.99 | C51: 41.99
A52: 1731633998973276993 | B52: 66.99 | C52: 42.99
A53: 1731634006967948097 | B53: 79.99 | C53: 52.99
... A80: 1731996018253337409 | B80: 99.99 | C80: 59.99
