Workbook

Sheet 数据源粘贴在这里
A1: [日期范围]: 2024-11-28 ~ 2024-12-25
A3: 达人昵称 | B3: 达人ID | C3: 视频信息 | D3: 视频ID | E3: 发布时间 | F3: 商品 | G3: 视频vv | H3: 点赞数 | I3: 评论数 | J3: 分享数 | K3: 新增粉丝数 | L3: 引流次数 | M3: 商品曝光次数 | N3: 商品点击次数 | O3: 视频成交用户数 | P3: 视频成交订单数 | Q3: 视频成交商品件数 | R3: 视频成交金额 ($) | S3: GPM ($) | T3: 归因于可购物视频的商品交易总额 ($) | U3: 曝光点击率 | V3: 引流率 | W3: 视频完播率 | X3: 点击成交转化率 | Y3: PID | Z3: 是否开单达人 | AA3: 店铺名 | AB3: 商务还是剪辑 | AC3: 日期 | AD3: SPU
A4: aliciathecoffeequeen | B4: 6799089893735269381 | C4: I swear to you - you will LIVE in this hoodie and have ZERO regrets about buying it! #tiktokshopblackfriday #hoodie #loungewear | D4: 7437574567259950366 | E4: 45611.436 | F4: Hatant acid wash hoodie pullover oversized heavyweight cotton blend fleeced inside fabric comfy and baggy hoodies suitable for men and women faded craf vintage style hoodie | G4: 15618 | H4: 117 | I4: 5 | J4: 2 | K4: 1 | L4: 0 | M4: 16946 | N4: 1001 | O4: 12 | P4: 12 | Q4: 12 | R4: 384.44 | S4: 24.62 | T4: 384.44 | U4: 0.0641 | V4: 0 | W4: 0.0079 | X4: 0.012 | Y4: =IFERROR(VLOOKUP(F:F,#REF!,2,0),"需要手动检查") -> 需要手动检查 | Z4: =IF(R4>0,"是","否") -> 是 | AA4: 3店-Faiable Comfywear | AB4: 商务 | AC4: =YEAR(E4)&"/"&MONTH(E4)&"/"&DAY(E4) -> 2024/11/15 | AD4: =VLOOKUP(Y4,#REF!,2,FALSE) -> #REF!
A5: itttisssiii | B5: 6910792633246467077 | C5: #fyp #ootd #nooutfitrepeating #fit #schoolfit | D5: 7434966566338301227 | E5: 45604.408 | F5: Hatant Stylish Street Fashion Pullover for Women with Soft Batwing Sleeves and Big Round Neck - Breathable and Comfortable Casual Sweatshirt for All-Day Wear | G5: 136951 | H5: 19546 | I5: 53 | J5: 94 | K5: 402 | L5: 5 | M5: 196486 | N5: 20204 | O5: 6 | P5: 6 | Q5: 6 | R5: 267.94 | S5: 1.96 | T5: 267.94 | U5: 0.1475 | V5: 0.0026 | W5: 0.0952 | X5: 0.0003 | Y5: =IFERROR(VLOOKUP(F:F,#REF!,2,0),"需要手动检查") -> 需要手动检查 | Z5: =IF(R5>0,"是","否") -> 是 | AA5: 3店-Faiable Comfywear | AB5: 商务 | AC5: =YEAR(E5)&"/"&MONTH(E5)&"/"&DAY(E5) -> 2024/11/8 | AD5: =VLOOKUP(Y5,#REF!,2,FALSE) -> #REF!
A6: liliannahope | B6: 6639452985867337734 | D6: 7419426640666676511 | E6: 45562.531 | F6: Hatant Stylish Street Fashion Pullover for Women with Soft Batwing Sleeves and Big Round Neck - Breathable and Comfortable Casual Sweatshirt for All-Day Wear | G6: 18401 | H6: 623 | I6: 0 | J6: 7 | K6: 1 | L6: 0 | M6: 20318 | N6: 816 | O6: 6 | P6: 6 | Q6: 6 | R6: 257.94 | S6: 14.02 | T6: 297.03 | U6: 0.0443 | V6: 0 | W6: 0.021 | X6: 0.0074 | Y6: =IFERROR(VLOOKUP(F:F,#REF!,2,0),"需要手动检查") -> 需要手动检查 | Z6: =IF(R6>0,"是","否") -> 是 | AA6: 3店-Faiable Comfywear | AB6: 商务 | AC6: =YEAR(E6)&"/"&MONTH(E6)&"/"&DAY(E6) -> 2024/9/27 | AD6: =VLOOKUP(Y6,#REF!,2,FALSE) -> #REF!
A7: thesiuhn7oh | B7: 7301470144705725486 | C7: the cutest way to do oversized #oversized #sweatshirt #sweatshirtstyle #oversizedsweater #fashiontrend #fashiontiktok | D7: 7436732817515482410 | E7: 45609.168 | F7: Hatant Stylish Street Fashion Pullover for Women with Soft Batwing Sleeves and Big Round Neck - Breathable and Comfortable Casual Sweatshirt for All-Day Wear | G7: 3547 | H7: 29 | I7: 0 | J7: 3 | K7: 0 | L7: 0 | M7: 3764 | N7: 90 | O7: 3 | P7: 4 | Q7: 5 | R7: 233.95 | S7: 65.96 | T7: 279.94 | U7: 0.0254 | V7: 0 | W7: 0.0048 | X7: 0.0444 | Y7: =IFERROR(VLOOKUP(F:F,#REF!,2,0),"需要手动检查") -> 需要手动检查 | Z7: =IF(R7>0,"是","否") -> 是 | AA7: 3店-Faiable Comfywear | AB7: 商务 | AC7: =YEAR(E7)&"/"&MONTH(E7)&"/"&DAY(E7) -> 2024/11/13 | AD7: =VLOOKUP(Y7,#REF!,2,FALSE) -> #REF!
A8: ariyoderrr | B8: 14945948 | D8: 7413494991592443166 | E8: 45546.547 | F8: Hatant Stylish Street Fashion Pullover for Women with Soft Batwing Sleeves and Big Round Neck - Breathable and Comfortable Casual Sweatshirt for All-Day Wear | G8: 6317 | H8: 59 | I8: 0 | J8: 2 | K8: 1 | L8: 0 | M8: 6856 | N8: 158 | O8: 4 | P8: 4 | Q8: 4 | R8: 171.96 | S8: 27.22 | T8: 171.96 | U8: 0.025 | V8: 0 | W8: 0.0103 | X8: 0.0253 | Y8: =IFERROR(VLOOKUP(F:F,#REF!,2,0),"需要手动检查") -> 需要手动检查 | Z8: =IF(R8>0,"是","否") -> 是 | AA8: 3店-Faiable Comfywear | AB8: 商务 | AC8: =YEAR(E8)&"/"&MONTH(E8)&"/"&DAY(E8) -> 2024/9/11 | AD8: =VLOOKUP(Y8,#REF!,2,FALSE) -> #REF!
A9: avedaviis | B9: 6616682790505906182 | C9: byeee need more colors #offtheshouldertop #offtheshouldersweatshirt #loungewearstyle #comfystyle | D9: 7433984616203078942 | E9: 45601.762 | F9: Hatant Stylish Street Fashion Pullover for Women with Soft Batwing Sleeves and Big Round Neck - Breathable and Comfortable Casual Sweatshirt for All-Day Wear | G9: 5669 | H9: 39 | I9: 0 | J9: 0 | K9: 1 | L9: 0 | M9: 6433 | N9: 203 | O9: 3 | P9: 3 | Q9: 3 | R9: 137.06 | S9: 24.18 | T9: 229.04 | U9: 0.0358 | V9: 0 | W9: 0.0023 | X9: 0.0148 | Y9: =IFERROR(VLOOKUP(F:F,#REF!,2,0),"需要手动检查") -> 需要手动检查 | Z9: =IF(R9>0,"是","否") -> 是 | AA9: 3店-Faiable Comfywear | AB9: 商务 | AC9: =YEAR(E9)&"/"&MONTH(E9)&"/"&DAY(E9) -> 2024/11/5 | AD9: =VLOOKUP(Y9,#REF!,2,FALSE) -> #REF!
A10: dyn_alva | B10: 6806760359799735301 | C10: Acid wash hoodie sizing‼️ #acidwashhoodie #acidwash #hoodie #fall | D10: 7436108318289956138 | E10: 45607.485 | F10: Hatant acid wash hoodie pullover oversized heavyweight cotton blend fleeced inside fabric comfy and baggy hoodies suitable for men and women faded craf vintage style hoodie | G10: 3409 | H10: 26 | I10: 0 | J10: 0 | K10: 2 | L10: 0 | M10: 3821 | N10: 305 | O10: 4 | P10: 4 | Q10: 4 | R10: 136.96 | S10: 40.18 | T10: 136.96 | U10: 0.0895 | V10: 0 | W10: 0.0179 | X10: 0.0131 | Y10: =IFERROR(VLOOKUP(F:F,#REF!,2,0),"需要手动检查") -> 需要手动检查 | Z10: =IF(R10>0,"是","否") -> 是 | AA10: 3店-Faiable Comfywear | AB10: 商务 | AC10: =YEAR(E10)&"/"&MONTH(E10)&"/"&DAY(E10) -> 2024/11/11 | AD10: =VLOOKUP(Y10,#REF!,2,FALSE) -> #REF!
A11: l4mebe4n | B11: 7300300908323603499 | C11: like OBSESSED ??? | D11: 7437935508342410542 | E11: 45612.409 | F11: Hatant Stylish Street Fashion Pullover for Women with Soft Batwing Sleeves and Big Round Neck - Breathable and Comfortable Casual Sweatshirt for All-Day Wear | G11: 5250 | H11: 212 | I11: 0 | J11: 4 | K11: 0 | L11: 0 | M11: 5814 | N11: 481 | O11: 2 | P11: 3 | Q11: 3 | R11: 133.3 | S11: 25.39 | T11: 133.3 | U11: 0.0916 | V11: 0 | W11: 0.0434 | X11: 0.0062 | Y11: =IFERROR(VLOOKUP(F:F,#REF!,2,0),"需要手动检查") -> 需要手动检查 | Z11: =IF(R11>0,"是","否") -> 是 | AA11: 3店-Faiable Comfywear | AB11: 商务 | AC11: =YEAR(E11)&"/"&MONTH(E11)&"/"&DAY(E11) -> 2024/11/16 | AD11: =VLOOKUP(Y11,#REF!,2,FALSE) -> #REF!
A12: apricotolies | B12: 6532043493043355649 | C12: its just perfectly oversized #ootd #sweaterweather #hoodieszn #fall #winter #cleangirlaesthetic #ootw | D12: 7433191245385731374 | E12: 45599.624 | F12: Hatant Stylish Street Fashion Pullover for Women with Soft Batwing Sleeves and Big Round Neck - Breathable and Comfortable Casual Sweatshirt for All-Day Wear | G12: 2247 | H12: 23 | I12: 0 | J12: 0 | K12: 1 | L12: 0 | M12: 2407 | N12: 57 | O12: 3 | P12: 3 | Q12: 3 | R12: 125.06 | S12: 55.66 | T12: 125.06 | U12: 0.0254 | V12: 0 | W12: 0.0062 | X12: 0.0526 | Y12: =IFERROR(VLOOKUP(F:F,#REF!,2,0),"需要手动检查") -> 需要手动检查 | Z12: =IF(R12>0,"是","否") -> 是 | AA12: 3店-Faiable Comfywear | AB12: 商务 | AC12: =YEAR(E12)&"/"&MONTH(E12)&"/"&DAY(E12) -> 2024/11/3 | AD12: =VLOOKUP(Y12,#REF!,2,FALSE) -> #REF!
A13: hblenkhorn | B13: 6812754345839690757 | C13: the comfiest off the shoulder top. #ootd #fyp | D13: 7437638295854517550 | E13: 45611.608 | F13: Hatant Stylish Street Fashion Pullover for Women with Soft Batwing Sleeves and Big Round Neck - Breathable and Comfortable Casual Sweatshirt for All-Day Wear | G13: 9274 | H13: 259 | I13: 2 | J13: 2 | K13: 6 | L13: 0 | M13: 10222 | N13: 470 | O13: 2 | P13: 2 | Q13: 2 | R13: 95.98 | S13: 10.35 | T13: 95.98 | U13: 0.0507 | V13: 0 | W13: 0.068 | X13: 0.0043 | Y13: =IFERROR(VLOOKUP(F:F,#REF!,2,0),"需要手动检查") -> 需要手动检查 | Z13: =IF(R13>0,"是","否") -> 是 | AA13: 3店-Faiable Comfywear | AB13: 商务 | AC13: =YEAR(E13)&"/"&MONTH(E13)&"/"&DAY(E13) -> 2024/11/15 | AD13: =VLOOKUP(Y13,#REF!,2,FALSE) -> #REF!
A14: tiiffancy | B14: 6727035502945797126 | C14: The crewneck is amazing + loving the acid wash!! ❤️‍🔥❤️‍🔥 wearing a large #fyp #ootd #fitcheck #fallfashion #fall #pinterest #pinterestinspo | D14: 7435343843718974751 | E14: 45605.425 | F14: Hatant Stylish Street Fashion Pullover for Women with Soft Batwing Sleeves and Big Round Neck - Breathable and Comfortable Casual Sweatshirt for All-Day Wear | G14: 4104 | H14: 43 | I14: 0 | J14: 0 | K14: 2 | L14: 0 | M14: 5424 | N14: 158 | O14: 2 | P14: 2 | Q14: 2 | R14: 95.98 | S14: 23.39 | T14: 95.98 | U14: 0.0385 | V14: 0 | W14: 0.0068 | X14: 0.0127 | Y14: =IFERROR(VLOOKUP(F:F,#REF!,2,0),"需要手动检查") -> 需要手动检查 | Z14: =IF(R14>0,"是","否") -> 是 | AA14: 3店-Faiable Comfywear | AB14: 商务 | AC14: =YEAR(E14)&"/"&MONTH(E14)&"/"&DAY(E14) -> 2024/11/9 | AD14: =VLOOKUP(Y14,#REF!,2,FALSE) -> #REF!
A15: marteen2003 | B15: 6805300488839808006 | C15: #faiable #offtheshoulder #sweater #crewneck #hoodie | D15: 7452024455636815134 | E15: 45650.376 | F15: Hatant Stylish Street Fashion Pullover for Women with Soft Batwing Sleeves and Big Round Neck - Breathable and Comfortable Casual Sweatshirt for All-Day Wear | G15: 1013 | H15: 20 | I15: 0 | J15: 0 | K15: 0 | L15: 0 | M15: 1094 | N15: 118 | O15: 2 | P15: 2 | Q15: 2 | R15: 90.16 | S15: 89 | T15: 90.16 | U15: 0.1165 | V15: 0 | W15: 0.0128 | X15: 0.0169 | Y15: =IFERROR(VLOOKUP(F:F,#REF!,2,0),"需要手动检查") -> 需要手动检查 | Z15: =IF(R15>0,"是","否") -> 是 | AA15: 3店-Faiable Comfywear | AB15: 商务 | AC15: =YEAR(E15)&"/"&MONTH(E15)&"/"&DAY(E15) -> 2024/12/24 | AD15: =VLOOKUP(Y15,#REF!,2,FALSE) -> #REF!
A16: miahowerton | B16: 6716266466914518022 | C16: off the shoulder crewnecks are my FAV @Hatant Brand #hatant #hatanthoodie #hatantvintage #fallfashion #hoodie #crewneck #ootd #loungewear #oufitinspo | D16: 7413864423065947423 | E16: 45547.542 | F16: Hatant Stylish Street Fashion Pullover for Women with Soft Batwing Sleeves and Big Round Neck - Breathable and Comfortable Casual Sweatshirt for All-Day Wear | G16: 2722 | H16: 84 | I16: 0 | J16: 3 | K16: 0 | L16: 0 | M16: 3478 | N16: 176 | O16: 2 | P16: 2 | Q16: 2 | R16: 90.16 | S16: 33.12 | T16: 90.16 | U16: 0.0647 | V16: 0 | W16: 0.0349 | X16: 0.0114 | Y16: =IFERROR(VLOOKUP(F:F,#REF!,2,0),"需要手动检查") -> 需要手动检查 | Z16: =IF(R16>0,"是","否") -> 是 | AA16: 3店-Faiable Comfywear | AB16: 商务 | AC16: =YEAR(E16)&"/"&MONTH(E16)&"/"&DAY(E16) -> 2024/9/12 | AD16: =VLOOKUP(Y16,#REF!,2,FALSE) -> #REF!
A17: kassie_____ | B17: 5731360 | C17: Today’s gym fit. #oversizedsweaters #pumpcovers #versatilesweaters #tiktokshopblackfriday | D17: 7441369823705156907 | E17: 45621.664 | F17: Hatant Stylish Street Fashion Pullover for Women with Soft Batwing Sleeves and Big Round Neck - Breathable and Comfortable Casual Sweatshirt for All-Day Wear | G17: 1672 | H17: 77 | I17: 0 | J17: 1 | K17: 9 | L17: 0 | M17: 1793 | N17: 166 | O17: 1 | P17: 2 | Q17: 2 | R17: 87.38 | S17: 52.26 | T17: 87.38 | U17: 0.0993 | V17: 0 | W17: 0.1328 | X17: 0.012 | Y17: =IFERROR(VLOOKUP(F:F,#REF!,2,0),"需要手动检查") -> 需要手动检查 | Z17: =IF(R17>0,"是","否") -> 是 | AA17: 3店-Faiable Comfywear | AB17: 商务 | AC17: =YEAR(E17)&"/"&MONTH(E17)&"/"&DAY(E17) -> 2024/11/25 | AD17: =VLOOKUP(Y17,#REF!,2,FALSE) -> #REF!
A18: katiesantos_sahm65 | B18: 6786888663429301253 | C18: This oversize acid was hoodie is amazing. #oversizedhoodie #hoodie #acidwash #oversized #fyp | D18: 7448705237721828638 | E18: 45641.431 | F18: Hatant acid wash hoodie pullover oversized heavyweight cotton blend fleeced inside fabric comfy and baggy hoodies suitable for men and women faded craf vintage style hoodie | G18: 353 | H18: 6 | I18: 0 | J18: 0 | K18: 0 | L18: 0 | M18: 382 | N18: 8 | O18: 1 | P18: 2 | Q18: 2 | R18: 75.98 | S18: 215.24 | T18: 75.98 | U18: 0.0227 | V18: 0 | W18: 0.0028 | X18: 0.25 | Y18: =IFERROR(VLOOKUP(F:F,#REF!,2,0),"需要手动检查") -> 需要手动检查 | Z18: =IF(R18>0,"是","否") -> 是 | AA18: 3店-Faiable Comfywear | AB18: 商务 | AC18: =YEAR(E18)&"/"&MONTH(E18)&"/"&DAY(E18) -> 2024/12/15 | AD18: =VLOOKUP(Y18,#REF!,2,FALSE) -> #REF!
A19: melodylams | B19: 6684261312363545606 | D19: 7443692040837270815 | E19: 45627.922 | F19: Hatant acid wash hoodie pullover oversized heavyweight cotton blend fleeced inside fabric comfy and baggy hoodies suitable for men and women faded craf vintage style hoodie | G19: 513 | H19: 21 | I19: 1 | J19: 0 | K19: 0 | L19: 0 | M19: 509 | N19: 15 | O19: 1 | P19: 2 | Q19: 2 | R19: 75.98 | S19: 148.11 | T19: 75.98 | U19: 0.0292 | V19: 0 | W19: 0.0253 | X19: 0.1333 | Y19: =IFERROR(VLOOKUP(F:F,#REF!,2,0),"需要手动检查") -> 需要手动检查 | Z19: =IF(R19>0,"是","否") -> 是 | AA19: 3店-Faiable Comfywear | AB19: 商务 | AC19: =YEAR(E19)&"/"&MONTH(E19)&"/"&DAY(E19) -> 2024/12/1 | AD19: =VLOOKUP(Y19,#REF!,2,FALSE) -> #REF!
A20: momentswithliv | B20: 6822445842688771077 | C20: catching up on posting today ✌️😙 #ootd #comfyfits #faiablehoodie @Faiable Fashion @Faiable Comfywear #offtheshoulder #crewneck #acidwash #comfyoutfits #brandy | D20: 7429903423585127723 | E20: 45590.764 | F20: Hatant Stylish Street Fashion Pullover for Women with Soft Batwing Sleeves and Big Round Neck - Breathable and Comfortable Casual Sweatshirt for All-Day Wear | G20: 91 | H20: 0 | I20: 0 | J20: 0 | K20: 0 | L20: 0 | M20: 119 | N20: 1 | O20: 1 | P20: 2 | Q20: 2 | R20: 75.38 | S20: 828.35 | T20: 75.38 | U20: 0.011 | V20: 0 | W20: 0.033 | X20: 2 | Y20: =IFERROR(VLOOKUP(F:F,#REF!,2,0),"需要手动检查") -> 需要手动检查 | Z20: =IF(R20>0,"是","否") -> 是 | AA20: 3店-Faiable Comfywear | AB20: 商务 | AC20: =YEAR(E20)&"/"&MONTH(E20)&"/"&DAY(E20) -> 2024/10/25 | AD20: =VLOOKUP(Y20,#REF!,2,FALSE) -> #REF!
A21: lovebutts | B21: 154392151454416896 | C21: #fypage #ootd | D21: 7448341638889409835 | E21: 45640.451 | F21: Hatant acid wash hoodie pullover oversized heavyweight cotton blend fleeced inside fabric comfy and baggy hoodies suitable for men and women faded craf vintage style hoodie | G21: 4784 | H21: 160 | I21: 4 | J21: 2 | K21: 0 | L21: 0 | M21: 5205 | N21: 133 | O21: 2 | P21: 2 | Q21: 2 | R21: 63.98 | S21: 13.37 | T21: 63.98 | U21: 0.0278 | V21: 0 | W21: 0.0477 | X21: 0.015 | Y21: =IFERROR(VLOOKUP(F:F,#REF!,2,0),"需要手动检查") -> 需要手动检查 | Z21: =IF(R21>0,"是","否") -> 是 | AA21: 3店-Faiable Comfywear | AB21: 商务 | AC21: =YEAR(E21)&"/"&MONTH(E21)&"/"&DAY(E21) -> 2024/12/14 | AD21: =VLOOKUP(Y21,#REF!,2,FALSE) -> #REF!
A22: thesiuhn7oh | B22: 7301470144705725486 | C22: omg cutest oversized look possibly ever #oversized #sweatshirt #sweatshirtstyle #oversizedsweater #fashiontiktok | D22: 7438970816114593070 | E22: 45615.199 | F22: Hatant Stylish Street Fashion Pullover for Women with Soft Batwing Sleeves and Big Round Neck - Breathable and Comfortable Casual Sweatshirt for All-Day Wear | G22: 631 | H22: 5 | I22: 0 | J22: 0 | K22: 1 | L22: 0 | M22: 667 | N22: 32 | O22: 1 | P22: 1 | Q22: 1 | R22: 53.99 | S22: 85.56 | T22: 107.98 | U22: 0.0507 | V22: 0 | W22: 0.019 | X22: 0.0313 | Y22: =IFERROR(VLOOKUP(F:F,#REF!,2,0),"需要手动检查") -> 需要手动检查 | Z22: =IF(R22>0,"是","否") -> 是 | AA22: 3店-Faiable Comfywear | AB22: 商务 | AC22: =YEAR(E22)&"/"&MONTH(E22)&"/"&DAY(E22) -> 2024/11/19 | AD22: =VLOOKUP(Y22,#REF!,2,FALSE) -> #REF!
A23: malayziamarie | B23: 7271352612913021995 | C23: Size Xl , Gonna have to get in a few more colors because im kind of obsessed. 🖤 #fyp #offtheshouldersweater | D23: 7441238665432517919 | E23: 45621.31 | F23: Hatant Stylish Street Fashion Pullover for Women with Soft Batwing Sleeves and Big Round Neck - Breathable and Comfortable Casual Sweatshirt for All-Day Wear | G23: 1170 | H23: 17 | I23: 1 | J23: 1 | K23: 0 | L23: 0 | M23: 1379 | N23: 106 | O23: 1 | P23: 1 | Q23: 1 | R23: 49.99 | S23: 42.73 | T23: 49.99 | U23: 0.0906 | V23: 0 | W23: 0.194 | X23: 0.0094 | Y23: =IFERROR(VLOOKUP(F:F,#REF!,2,0),"需要手动检查") -> 需要手动检查 | Z23: =IF(R23>0,"是","否") -> 是 | AA23: 3店-Faiable Comfywear | AB23: 商务 | AC23: =YEAR(E23)&"/"&MONTH(E23)&"/"&DAY(E23) -> 2024/11/25 | AD23: =VLOOKUP(Y23,#REF!,2,FALSE) -> #REF!
A24: nphiynhi | B24: 6642365632397262853 | C24: Like a cozy blanket on me 🎧💕 #sweatshirt #offshoulder #cozyclothes #TikTokShopBlackFriday #TikTokShopHolidayHaul #TikTokShopCyberMonday #giftideas | D24: 7436505604610411822 | E24: 45608.555 | F24: Hatant Stylish Street Fashion Pullover for Women with Soft Batwing Sleeves and Big Round Neck - Breathable and Comfortable Casual Sweatshirt for All-Day Wear | G24: 418 | H24: 7 | I24: 0 | J24: 0 | K24: 0 | L24: 0 | M24: 539 | N24: 25 | O24: 1 | P24: 1 | Q24: 1 | R24: 49.99 | S24: 119.59 | T24: 49.99 | U24: 0.0598 | V24: 0 | W24: 0.0359 | X24: 0.04 | Y24: =IFERROR(VLOOKUP(F:F,#REF!,2,0),"需要手动检查") -> 需要手动检查 | Z24: =IF(R24>0,"是","否") -> 是 | AA24: 3店-Faiable Comfywear | AB24: 商务 | AC24: =YEAR(E24)&"/"&MONTH(E24)&"/"&DAY(E24) -> 2024/11/12 | AD24: =VLOOKUP(Y24,#REF!,2,FALSE) -> #REF!
A25: jules.t_ | B25: 128352 | C25: which way is your favorite? @Hatant Brand #hatant #hatanthoodie #hatantvintage 🫶🏼 | D25: 7422758501824433454 | E25: 45571.51 | F25: Hatant Stylish Street Fashion Pullover for Women with Soft Batwing Sleeves and Big Round Neck - Breathable and Comfortable Casual Sweatshirt for All-Day Wear | G25: 524 | H25: 3 | I25: 0 | J25: 1 | K25: 0 | L25: 0 | M25: 570 | N25: 12 | O25: 1 | P25: 1 | Q25: 1 | R25: 49.99 | S25: 95.4 | T25: 49.99 | U25: 0.0229 | V25: 0 | W25: 0.0592 | X25: 0.0833 | Y25: =IFERROR(VLOOKUP(F:F,#REF!,2,0),"需要手动检查") -> 需要手动检查 | Z25: =IF(R25>0,"是","否") -> 是 | AA25: 3店-Faiable Comfywear | AB25: 商务 | AC25: =YEAR(E25)&"/"&MONTH(E25)&"/"&DAY(E25) -> 2024/10/6 | AD25: =VLOOKUP(Y25,#REF!,2,FALSE) -> #REF!
A26: leaxjane | B26: 207073895185670144 | C26: This is a nice quality hoodie sweatshirt! It is fleece lined and so cozy! @Faiable Fashion @Faiable Comfywear #womensfashion #plussizefashion #midsizefashion #tiktokshopholidayhaul #winterfashion #giftideas #hoodie #oversized | D26: 7446771002828180779 | E26: 45636.219 | F26: Hatant acid wash hoodie pullover oversized heavyweight cotton blend fleeced inside fabric comfy and baggy hoodies suitable for men and women faded craf vintage style hoodie | G26: 474 | H26: 10 | I26: 0 | J26: 1 | K26: 1 | L26: 0 | M26: 566 | N26: 24 | O26: 1 | P26: 1 | Q26: 1 | R26: 45.99 | S26: 97.03 | T26: 45.99 | U26: 0.0506 | V26: 0 | W26: 0.0759 | X26: 0.0417 | Y26: =IFERROR(VLOOKUP(F:F,#REF!,2,0),"需要手动检查") -> 需要手动检查 | Z26: =IF(R26>0,"是","否") -> 是 | AA26: 3店-Faiable Comfywear | AB26: 商务 | AC26: =YEAR(E26)&"/"&MONTH(E26)&"/"&DAY(E26) -> 2024/12/10 | AD26: =VLOOKUP(Y26,#REF!,2,FALSE) -> #REF!
A27: everyday_tina | B27: 6804619634186077190 | C27: So cozy and comfy!! #outfitsinspo #tiktokshop #fyp | D27: 7440105853669149998 | E27: 45618.257 | F27: Hatant Stylish Street Fashion Pullover for Women with Soft Batwing Sleeves and Big Round Neck - Breathable and Comfortable Casual Sweatshirt for All-Day Wear | G27: 412 | H27: 2 | I27: 0 | J27: 0 | K27: 0 | L27: 0 | M27: 436 | N27: 26 | O27: 1 | P27: 1 | Q27: 1 | R27: 45.99 | S27: 111.63 | T27: 45.99 | U27: 0.0631 | V27: 0 | W27: 0.0024 | X27: 0.0385 | Y27: =IFERROR(VLOOKUP(F:F,#REF!,2,0),"需要手动检查") -> 需要手动检查 | Z27: =IF(R27>0,"是","否") -> 是 | AA27: 3店-Faiable Comfywear | AB27: 商务 | AC27: =YEAR(E27)&"/"&MONTH(E27)&"/"&DAY(E27) -> 2024/11/22 | AD27: =VLOOKUP(Y27,#REF!,2,FALSE) -> #REF!
A28: iamkay2024 | B28: 7288982162065441838 | C28: i mean RUN. 🏃‍♀️💙❄️ #sweater #sweaterweather #offtheshouldersweater #fall #winter #tiktokshopblackfriday | D28: 7438812703596072223 | E28: 45614.773 | F28: Hatant Stylish Street Fashion Pullover for Women with Soft Batwing Sleeves and Big Round Neck - Breathable and Comfortable Casual Sweatshirt for All-Day Wear | G28: 211 | H28: 3 | I28: 0 | J28: 0 | K28: 0 | L28: 0 | M28: 240 | N28: 5 | O28: 1 | P28: 1 | Q28: 1 | R28: 45.99 | S28: 217.96 | T28: 91.07 | U28: 0.0237 | V28: 0 | W28: 0.0284 | X28: 0.2 | Y28: =IFERROR(VLOOKUP(F:F,#REF!,2,0),"需要手动检查") -> 需要手动检查 | Z28: =IF(R28>0,"是","否") -> 是 | AA28: 3店-Faiable Comfywear | AB28: 商务 | AC28: =YEAR(E28)&"/"&MONTH(E28)&"/"&DAY(E28) -> 2024/11/18 | AD28: =VLOOKUP(Y28,#REF!,2,FALSE) -> #REF!
A29: chamley_teaches | B29: 6783887103179113477 | C29: if you loved the acid wash hoodie, you will love the crewneck 🫶🏽 wearing size medium !! #tiktokshop #tiktokshopfinds #acidwash #hoodie #hoodies #hoodieszn #acidwashhoodie #crewneck #crewnecksweatshirt #oversizedhoodie | D29: 7431556464403057951 | E29: 45595.219 | F29: Hatant Stylish Street Fashion Pullover for Women with Soft Batwing Sleeves and Big Round Neck - Breathable and Comfortable Casual Sweatshirt for All-Day Wear | G29: 5487 | H29: 33 | I29: 0 | J29: 1 | K29: 0 | L29: 0 | M29: 6056 | N29: 97 | O29: 1 | P29: 1 | Q29: 1 | R29: 45.99 | S29: 8.38 | T29: 91.07 | U29: 0.0177 | V29: 0 | W29: 0.027 | X29: 0.0103 | Y29: =IFERROR(VLOOKUP(F:F,#REF!,2,0),"需要手动检查") -> 需要手动检查 | Z29: =IF(R29>0,"是","否") -> 是 | AA29: 3店-Faiable Comfywear | AB29: 商务 | AC29: =YEAR(E29)&"/"&MONTH(E29)&"/"&DAY(E29) -> 2024/10/30 | AD29: =VLOOKUP(Y29,#REF!,2,FALSE) -> #REF!
A30: ariyoderrr | B30: 14945948 | C30: Linked above^^^ im 5’4 and got a size medium #fyp #crewneck #sweaterweather #cutesweatshirts #cutefalloutfits #collegeoutfit #comfy #pink #offtheshoulder #trending #viral | D30: 7412392895409343775 | E30: 45543.577 | F30: Hatant Stylish Street Fashion Pullover for Women with Soft Batwing Sleeves and Big Round Neck - Breathable and Comfortable Casual Sweatshirt for All-Day Wear | G30: 844 | H30: 2 | I30: 0 | J30: 0 | K30: 0 | L30: 0 | M30: 984 | N30: 27 | O30: 1 | P30: 1 | Q30: 1 | R30: 45.99 | S30: 54.49 | T30: 45.99 | U30: 0.032 | V30: 0 | W30: 0.0569 | X30: 0.037 | Y30: =IFERROR(VLOOKUP(F:F,#REF!,2,0),"需要手动检查") -> 需要手动检查 | Z30: =IF(R30>0,"是","否") -> 是 | AA30: 3店-Faiable Comfywear | AB30: 商务 | AC30: =YEAR(E30)&"/"&MONTH(E30)&"/"&DAY(E30) -> 2024/9/8 | AD30: =VLOOKUP(Y30,#REF!,2,FALSE) -> #REF!
A31: avedaviis | B31: 6616682790505906182 | C31: sweatshirts all day 🫶🏼 | D31: 7434733452278156575 | E31: 45603.78 | F31: Hatant Stylish Street Fashion Pullover for Women with Soft Batwing Sleeves and Big Round Neck - Breathable and Comfortable Casual Sweatshirt for All-Day Wear | G31: 592 | H31: 6 | I31: 2 | J31: 0 | K31: 0 | L31: 0 | M31: 640 | N31: 13 | O31: 1 | P31: 1 | Q31: 1 | R31: 45.08 | S31: 76.15 | T31: 45.08 | U31: 0.022 | V31: 0 | W31: 0.027 | X31: 0.0769 | Y31: =IFERROR(VLOOKUP(F:F,#REF!,2,0),"需要手动检查") -> 需要手动检查 | Z31: =IF(R31>0,"是","否") -> 是 | AA31: 3店-Faiable Comfywear | AB31: 商务 | AC31: =YEAR(E31)&"/"&MONTH(E31)&"/"&DAY(E31) -> 2024/11/7 | AD31: =VLOOKUP(Y31,#REF!,2,FALSE) -> #REF!
... A44: keriannkuzmin | B44: 6768690888581760005 | C44: Something about an oversized hoodie🎀 #hoodie #jacket #fashion #hoodieszn | D44: 7446893980408679722 | E44: 45636.55 | F44: Hatant acid wash hoodie pullover oversized heavyweight cotton blend fleeced inside fabric comfy and baggy hoodies suitable for men and women faded craf vintage style hoodie | G44: 907 | H44: 60 | I44: 2 | J44: 3 | K44: 0 | L44: 0 | M44: 1030 | N44: 8 | O44: 1 | P44: 1 | Q44: 1 | R44: 25.99 | S44: 28.65 | T44: 25.99 | U44: 0.0088 | V44: 0 | W44: 0.0485 | X44: 0.125 | Y44: =IFERROR(VLOOKUP(F:F,#REF!,2,0),"需要手动检查") -> 需要手动检查 | Z44: =IF(R44>0,"是","否") -> 是 | AA44: 3店-Faiable Comfywear | AB44: 商务 | AC44: =YEAR(E44)&"/"&MONTH(E44)&"/"&DAY(E44) -> 2024/12/10 | AD44: =VLOOKUP(Y44,#REF!,2,FALSE) -> #REF!
A45: emilyannmcgill | B45: 7117440140370789422 | D45: 7403933968673885471 | E45: 45520.782 | F45: Hatant Sweatshirt for Women Acid Wash Athletic Hoodie Heritage Fleece V-neck Long Sleeve Hoodie Fleece Women Sweatshirt,nice fell soft fabric,perfect crop length,suitable for running errands, relaxing at home,flattering style washed hoodie | G45: 37 | H45: 7 | I45: 0 | J45: 0 | K45: 0 | L45: 0 | M45: 44 | N45: 10 | O45: 1 | P45: 1 | Q45: 1 | R45: 13.03 | S45: 352.16 | T45: 13.03 | U45: 0.2703 | V45: 0 | W45: 0 | X45: 0.1 | Y45: =IFERROR(VLOOKUP(F:F,#REF!,2,0),"需要手动检查") -> 需要手动检查 | Z45: =IF(R45>0,"是","否") -> 是 | AA45: 3店-Faiable Comfywear | AB45: 商务 | AC45: =YEAR(E45)&"/"&MONTH(E45)&"/"&DAY(E45) -> 2024/8/16 | AD45: =VLOOKUP(Y45,#REF!,2,FALSE) -> #REF!
A46: aleksamink | B46: 25195448 | C46: Thick and affordable #tiktokshop #fashionfinds #thick #curves #bodypositivity | D46: 7452570087699074346 | E46: 45651.846 | F46: Hatant acid wash hoodie pullover oversized heavyweight cotton blend fleeced inside fabric comfy and baggy hoodies suitable for men and women faded craf vintage style hoodie | G46: 2067 | H46: 104 | I46: 6 | J46: 0 | K46: 2 | L46: 0 | M46: 1876 | N46: 23 | O46: 0 | P46: 0 | Q46: 0 | R46: 0 | S46: 0 | T46: 0 | U46: 0.0111 | V46: 0 | W46: 0.0479 | X46: 0 | Y46: =IFERROR(VLOOKUP(F:F,#REF!,2,0),"需要手动检查") -> 需要手动检查 | Z46: =IF(R46>0,"是","否") -> 否 | AA46: 3店-Faiable Comfywear | AB46: 商务 | AC46: =YEAR(E46)&"/"&MONTH(E46)&"/"&DAY(E46) -> 2024/12/25 | AD46: =VLOOKUP(Y46,#REF!,2,FALSE) -> #REF!
A47: natalia199326 | B47: 6745777028622435333 | C47: Hatant acid wash hoodie pullov Sudadera de muy buena calidad perfecta para temporada de frío 🫶 #hatant #wash #sudaderas #sudadera #sudaderaoversize #comoda #Navidad #Christmas | D47: 7452369711326678315 | E47: 45651.306 | F47: Hatant acid wash hoodie pullover oversized heavyweight cotton blend fleeced inside fabric comfy and baggy hoodies suitable for men and women faded craf vintage style hoodie | G47: 448 | H47: 23 | I47: 6 | J47: 10 | K47: 1 | L47: 0 | M47: 456 | N47: 19 | O47: 0 | P47: 0 | Q47: 0 | R47: 0 | S47: 0 | T47: 0 | U47: 0.0424 | V47: 0 | W47: 0.0603 | X47: 0 | Y47: =IFERROR(VLOOKUP(F:F,#REF!,2,0),"需要手动检查") -> 需要手动检查 | Z47: =IF(R47>0,"是","否") -> 否 | AA47: 3店-Faiable Comfywear | AB47: 商务 | AC47: =YEAR(E47)&"/"&MONTH(E47)&"/"&DAY(E47) -> 2024/12/25 | AD47: =VLOOKUP(Y47,#REF!,2,FALSE) -> #REF!
A48: therealtina_4444 | B48: 6924048352968606726 | C48: Size small true size, many different colors and styles to choose from #musthaves #tiktokshop #sweater #fashion #smallbusiness #fyp #womensfashion | D48: 7452365023457987871 | E48: 45651.294 | F48: Hatant Stylish Street Fashion Pullover for Women with Soft Batwing Sleeves and Big Round Neck - Breathable and Comfortable Casual Sweatshirt for All-Day Wear | G48: 374 | H48: 34 | I48: 6 | J48: 0 | K48: 1 | L48: 0 | M48: 419 | N48: 46 | O48: 0 | P48: 0 | Q48: 0 | R48: 0 | S48: 0 | T48: 0 | U48: 0.123 | V48: 0 | W48: 0.0561 | X48: 0 | Y48: =IFERROR(VLOOKUP(F:F,#REF!,2,0),"需要手动检查") -> 需要手动检查 | Z48: =IF(R48>0,"是","否") -> 否 | AA48: 3店-Faiable Comfywear | AB48: 商务 | AC48: =YEAR(E48)&"/"&MONTH(E48)&"/"&DAY(E48) -> 2024/12/25 | AD48: =VLOOKUP(Y48,#REF!,2,FALSE) -> #REF!
A49: harabaraaa | B49: 4312452 | C49: #gossipgirl #oversizedshirt #cozy #tiktokshopfinds | D49: 7452273728341216555 | E49: 45651.047 | F49: Hatant Stylish Street Fashion Pullover for Women with Soft Batwing Sleeves and Big Round Neck - Breathable and Comfortable Casual Sweatshirt for All-Day Wear | G49: 296 | H49: 5 | I49: 0 | J49: 0 | K49: 0 | L49: 0 | M49: 324 | N49: 3 | O49: 0 | P49: 0 | Q49: 0 | R49: 0 | S49: 0 | T49: 0 | U49: 0.0101 | V49: 0 | W49: 0.0405 | X49: 0 | Y49: =IFERROR(VLOOKUP(F:F,#REF!,2,0),"需要手动检查") -> 需要手动检查 | Z49: =IF(R49>0,"是","否") -> 否 | AA49: 3店-Faiable Comfywear | AB49: 商务 | AC49: =YEAR(E49)&"/"&MONTH(E49)&"/"&DAY(E49) -> 2024/12/25 | AD49: =VLOOKUP(Y49,#REF!,2,FALSE) -> #REF!
A50: harabaraaa | B50: 4312452 | C50: #cozy #oversized #tiktokshop #tiktokshopfinds | D50: 7452272707929902382 | E50: 45651.045 | F50: Hatant Stylish Street Fashion Pullover for Women with Soft Batwing Sleeves and Big Round Neck - Breathable and Comfortable Casual Sweatshirt for All-Day Wear | G50: 295 | H50: 6 | I50: 0 | J50: 0 | K50: 0 | L50: 0 | M50: 287 | N50: 6 | O50: 0 | P50: 0 | Q50: 0 | R50: 0 | S50: 0 | T50: 0 | U50: 0.0203 | V50: 0 | W50: 0.0203 | X50: 0 | Y50: =IFERROR(VLOOKUP(F:F,#REF!,2,0),"需要手动检查") -> 需要手动检查 | Z50: =IF(R50>0,"是","否") -> 否 | AA50: 3店-Faiable Comfywear | AB50: 商务 | AC50: =YEAR(E50)&"/"&MONTH(E50)&"/"&DAY(E50) -> 2024/12/25 | AD50: =VLOOKUP(Y50,#REF!,2,FALSE) -> #REF!
A51: kairienos | B51: 6952974567241565189 | C51: MERRY CHRISTMAS EVE ❤️💋🎁 @Faiable Fashion #faiable #faiablehoodie #faiablefashion #hoodie #hoodieszn #hoodieseason #hoodiesthathoodie #redhoodie #christmaseve #christmas | D51: 7452206129846865198 | E51: 45650.865 | F51: Hatant acid wash hoodie pullover oversized heavyweight cotton blend fleeced inside fabric comfy and baggy hoodies suitable for men and women faded craf vintage style hoodie | G51: 591 | H51: 55 | I51: 15 | J51: 2 | K51: 0 | L51: 0 | M51: 637 | N51: 51 | O51: 0 | P51: 0 | Q51: 0 | R51: 0 | S51: 0 | T51: 0 | U51: 0.0863 | V51: 0 | W51: 0.0288 | X51: 0 | Y51: =IFERROR(VLOOKUP(F:F,#REF!,2,0),"需要手动检查") -> 需要手动检查 | Z51: =IF(R51>0,"是","否") -> 否 | AA51: 3店-Faiable Comfywear | AB51: 商务 | AC51: =YEAR(E51)&"/"&MONTH(E51)&"/"&DAY(E51) -> 2024/12/24 | AD51: =VLOOKUP(Y51,#REF!,2,FALSE) -> #REF!
A52: jennmalentacchi | B52: 6765262976972981253 | C52: I have loved these sweatpants since the day I got them. You can’t even tell how many times I have washed them.@Faiable Comfywear #Sweatpants #HatAant #Joggers #Pockets #Pajamas #Athletic #Loungewear #Leisurewear #ColdWeather #SweaterWeather #TikTokShop #TikTokFashion | D52: 7452102310211177758 | E52: 45650.586 | F52: Hatant heavyweight fleeced comfy and soft baggy sweatpants cotton 345gsm fabric S-2XL true size bottoms Elastic waistband drawstring | G52: 298 | H52: 9 | I52: 1 | J52: 0 | K52: 0 | L52: 0 | M52: 315 | N52: 3 | O52: 0 | P52: 0 | Q52: 0 | R52: 0 | S52: 0 | T52: 0 | U52: 0.0101 | V52: 0 | W52: 0.0201 | X52: 0 | Y52: =IFERROR(VLOOKUP(F:F,#REF!,2,0),"需要手动检查") -> 需要手动检查 | Z52: =IF(R52>0,"是","否") -> 否 | AA52: 3店-Faiable Comfywear | AB52: 商务 | AC52: =YEAR(E52)&"/"&MONTH(E52)&"/"&DAY(E52) -> 2024/12/24 | AD52: =VLOOKUP(Y52,#REF!,2,FALSE) -> #REF!
A53: momma_mya | B53: 6908047646339531781 | C53: Its so nice i love it. Gonna be worn to the gym for the next 6 months lmaooo #gymclothes #pumpcover #hoodieweather #hoodie #sweatshirtsesaon #gymtok #gymfit #pumpcovers #bodybuilding #bodybuilders #gymgirls #cozyseason | D53: 7452096927048469806 | E53: 45650.571 | F53: Hatant acid wash hoodie pullover oversized heavyweight cotton blend fleeced inside fabric comfy and baggy hoodies suitable for men and women faded craf vintage style hoodie | G53: 386 | H53: 22 | I53: 0 | J53: 2 | K53: 0 | L53: 0 | M53: 426 | N53: 14 | O53: 0 | P53: 0 | Q53: 0 | R53: 0 | S53: 0 | T53: 0 | U53: 0.0363 | V53: 0 | W53: 0.1399 | X53: 0 | Y53: =IFERROR(VLOOKUP(F:F,#REF!,2,0),"需要手动检查") -> 需要手动检查 | Z53: =IF(R53>0,"是","否") -> 否 | AA53: 3店-Faiable Comfywear | AB53: 商务 | AC53: =YEAR(E53)&"/"&MONTH(E53)&"/"&DAY(E53) -> 2024/12/24 | AD53: =VLOOKUP(Y53,#REF!,2,FALSE) -> #REF!
...
